<?xml version="1.0"?>
<robot name="xeros10">
  <link name="base_footprint"/>
  
  <joint name="base_footprint_joint" type="fixed">
    <parent link="base_footprint"/>
    <child link="base_link"/>
    <origin xyz="0 0 0" rpy="0 0 0"/>
  </joint>

  <link name="base_link">
    <inertial>
      <origin xyz="-0.26932 0.09524 -0.10623" rpy="0 0 0" />
      <mass value="4.0" />
      <inertia ixx="0.1" ixy="0" ixz="0" iyy="0.1" iyz="0" izz="0.1" />
    </inertial>
    <visual>
      <origin xyz="0 0 0" rpy="0 0 0" />
      <geometry>
        <mesh filename="package://xeros10_real/meshes/base_link.STL" scale="10 10 10"/>
      </geometry>
      <material name="light_blue">
        <color rgba="0.792156862745098 0.819607843137255 0.933333333333333 1" />
      </material>
    </visual>
    <collision>
      <origin xyz="0 0 0" rpy="0 0 0" />
      <geometry>
        <mesh filename="package://xeros10_real/meshes/base_link.STL" scale="10 10 10"/>
      </geometry>
    </collision>
  </link>

  <link name="wheel1">
    <inertial>
      <origin xyz="0 0 -0.026107" rpy="0 0 0" />
      <mass value="0.2" />
      <inertia ixx="0.001" ixy="0" ixz="0" iyy="0.001" iyz="0" izz="0.001" />
    </inertial>
    <visual>
      <origin xyz="0 0 0" rpy="0 0 0" />
      <geometry>
        <mesh filename="package://xeros10_real/meshes/wheel1.STL" scale="10 10 10"/>
      </geometry>
      <material name="light_blue">
        <color rgba="0.79216 0.81961 0.93333 1" />
      </material>
    </visual>
    <collision>
      <origin xyz="0 0 0" rpy="0 0 0" />
      <geometry>
        <mesh filename="package://xeros10_real/meshes/wheel1.STL" scale="10 10 10"/>
      </geometry>
    </collision>
  </link>

  <joint name="wheel1_joint" type="continuous">
    <origin xyz="-0.39469 0.32253 0.02" rpy="-2.0944 1.5708 0"/>
    <parent link="base_link" />
    <child link="wheel1" />
    <axis xyz="0 0 -1" />
  </joint>

  <link name="wheel2">
    <inertial>
      <origin xyz="0 0 -0.026107" rpy="0 0 0" />
      <mass value="0.2" />
      <inertia ixx="0.001" ixy="0" ixz="0" iyy="0.001" iyz="0" izz="0.001" />
    </inertial>
    <visual>
      <origin xyz="0 0 0" rpy="0 0 0" />
      <geometry>
        <mesh filename="package://xeros10_real/meshes/wheel2.STL" scale="10 10 10"/>
      </geometry>
      <material name="light_blue">
        <color rgba="0.79216 0.81961 0.93333 1" />
      </material>
    </visual>
    <collision>
      <origin xyz="0 0 0" rpy="0 0 0" />
      <geometry>
        <mesh filename="package://xeros10_real/meshes/wheel2.STL" scale="10 10 10"/>
      </geometry>
    </collision>
  </link>

  <joint name="wheel2_joint" type="continuous">
    <origin xyz="-0.39469 -0.11005 0.02" rpy="2.1029 1.5708 0" />
    <parent link="base_link" />
    <child link="wheel2" />
    <axis xyz="0 0 -1" />
  </joint>

  <link name="wheel3">
    <inertial>
      <origin xyz="0 0 -0.026107" rpy="0 0 0" />
      <mass value="0.2" />
      <inertia ixx="0.001" ixy="0" ixz="0" iyy="0.001" iyz="0" izz="0.001" />
    </inertial>
    <visual>
      <origin xyz="0 0 0" rpy="0 0 0" />
      <geometry>
        <mesh filename="package://xeros10_real/meshes/wheel3.STL" scale="10 10 10"/>
      </geometry>
      <material name="light_blue">
        <color rgba="0.79216 0.81961 0.93333 1" />
      </material>
    </visual>
    <collision>
      <origin xyz="0 0 0" rpy="0 0 0" />
      <geometry>
        <mesh filename="package://xeros10_real/meshes/wheel3.STL" scale="10 10 10"/>
      </geometry>
    </collision>
  </link>

  <joint name="wheel3_joint" type="continuous">
    <origin xyz="-0.019326 0.10667 0.02" rpy="0.0085408 1.5708 0" />
    <parent link="base_link" />
    <child link="wheel3" />
    <axis xyz="0 0 -1" />
  </joint>

  <link name="arm1">
    <inertial>
      <origin xyz="-0.039453 0 0.072344" rpy="0 0 0" />
      <mass value="0.1" />
      <inertia ixx="0.0005" ixy="0" ixz="0" iyy="0.0005" iyz="0" izz="0.0005" />
    </inertial>
    <visual>
      <origin xyz="0 0 0" rpy="0 0 0" />
      <geometry>
        <mesh filename="package://xeros10_real/meshes/arm1.STL" scale="10 10 10"/>
      </geometry>
      <material name="light_blue">
        <color rgba="0.79216 0.81961 0.93333 1" />
      </material>
    </visual>
    <collision>
      <origin xyz="0 0 0" rpy="0 0 0" />
      <geometry>
        <mesh filename="package://xeros10_real/meshes/arm1.STL" scale="10 10 10"/>
      </geometry>
    </collision>
  </link>

  <joint name="arm1_joint" type="revolute">
    <origin xyz="-0.25741 0.11476 0.38498" rpy="2.5206 1.5708 0" />
    <parent link="base_link" />
    <child link="arm1" />
    <axis xyz="0 0 -1" />
    <limit lower="0" upper="1.56" effort="100.0" velocity="1.0" />
  </joint>

  <link name="arm2">
    <inertial>
      <origin xyz="0 0.01 0" rpy="0 0 0" />
      <mass value="0.1" />
      <inertia ixx="0.0005" ixy="0" ixz="0" iyy="0.0005" iyz="0" izz="0.0005" />
    </inertial>
    <visual>
      <origin xyz="0 0 0" rpy="0 0 0" />
      <geometry>
        <mesh filename="package://xeros10_real/meshes/arm2.STL" scale="10 10 10"/>
      </geometry>
      <material name="light_blue">
        <color rgba="0.79216 0.81961 0.93333 1" />
      </material>
    </visual>
    <collision>
      <origin xyz="0 0 0" rpy="0 0 0" />
      <geometry>
        <mesh filename="package://xeros10_real/meshes/arm2.STL" scale="10 10 10"/>
      </geometry>
    </collision>
  </link>

  <joint name="arm2_point" type="prismatic">
    <origin xyz="-0.15 0.20563 0.085" rpy="-1.5708 0 0" />
    <parent link="arm1" />
    <child link="arm2" />
    <axis xyz="0 0 -1" />
    <limit lower="0" upper="0.38" effort="100.0" velocity="1.0" />
  </joint>

  <link name="lidar_link">
    <inertial>
      <origin xyz="0 0 0" rpy="0 0 0" />
      <mass value="0.1" />
      <inertia ixx="0.0001" ixy="0" ixz="0" iyy="0.0001" iyz="0" izz="0.0001" />
    </inertial>
    <visual>
      <origin xyz="0 0 0" rpy="0 0 0" />
      <geometry>
        <cylinder radius="0.04" length="0.04" />
      </geometry>
      <material name="black">
        <color rgba="0.1 0.1 0.1 1" />
      </material>
    </visual>
    <collision>
      <origin xyz="0 0 0" rpy="0 0 0" />
      <geometry>
        <cylinder radius="0.04" length="0.04" />
      </geometry>
    </collision>
  </link>

  <joint name="lidar_joint" type="fixed">
    <origin xyz="-0.15 -0.04 0.15" rpy="0 0 0" />
    <parent link="base_link" />
    <child link="lidar_link" />
  </joint>
  
  <link name="camera_link">
    <visual>
      <origin xyz="0 0 0" rpy="0 0 0"/>
      <geometry>
        <box size="0.04 0.03 0.04"/>
      </geometry>
      <material name="black">
        <color rgba="0 0 0 1"/>
      </material>
    </visual>
    <inertial>
      <mass value="0.05" />
      <origin xyz="0 0 0" rpy="0 0 0"/>
      <inertia ixx="0.0001" ixy="0" ixz="0" iyy="0.0001" iyz="0" izz="0.0001" />
    </inertial>
  </link>

  <joint name="camera_joint" type="fixed">
    <parent link="arm2"/>
    <child link="camera_link"/>
    <origin xyz="-0.07 0.005 0.05" rpy="0 -1.57 0"/> </joint>

  <link name="camera_link_optical"></link>

  <joint name="camera_optical_joint" type="fixed">
    <parent link="camera_link"/>
    <child link="camera_link_optical"/>
    <origin xyz="0 0 0" rpy="-1.5708 0 -1.5708"/>
  </joint>
  
  <gazebo reference="wheel1">
    <mu1>1.0</mu1>
    <mu2>1.0</mu2>
  </gazebo>

  <gazebo reference="wheel2">
    <mu1>1.0</mu1>
    <mu2>1.0</mu2>
  </gazebo>

  <gazebo reference="wheel3">
    <mu1>1.0</mu1>
    <mu2>1.0</mu2>
  </gazebo>
  
  <gazebo>
    <plugin name="gazebo_ros_planar_move" filename="libgazebo_ros_planar_move.so">
      <ros>
        <remapping>cmd_vel:=cmd_vel</remapping>
        <remapping>odom:=odom</remapping>
      </ros>

      <update_rate>50.0</update_rate>
      <publish_rate>50.0</publish_rate>

      <publish_odom>true</publish_odom>
      <publish_odom_tf>true</publish_odom_tf>

      <odometry_frame>odom</odometry_frame>
      <robot_base_frame>base_footprint</robot_base_frame>
    </plugin>
  </gazebo>
  
  <ros2_control name="GazeboSystem" type="system">
    <hardware>
      <plugin>gazebo_ros2_control/GazeboSystem</plugin>
    </hardware>
    
    <joint name="arm1_joint">
      <command_interface name="position"/> <state_interface name="position"/>
      <state_interface name="velocity"/>
    </joint>

    <joint name="arm2_point">
      <command_interface name="position"/> <state_interface name="position"/>
      <state_interface name="velocity"/>
    </joint>
  </ros2_control>
  
  <gazebo>
    <plugin name="gazebo_ros2_control" filename="libgazebo_ros2_control.so">
      <parameters>$(find xeros10_real)/config/arm_controllers.yaml</parameters>
      <robot_param>robot_description</robot_param>
      <robot_param_node>robot_state_publisher</robot_param_node>
    </plugin>
  </gazebo>

  <gazebo reference="lidar_link">
    <sensor name="lidar_sensor" type="ray">
      <pose>0 0 0 0 0 0</pose>
      <visualize>true</visualize> <update_rate>10.0</update_rate>
      <ray>
        <scan>
          <horizontal>
            <samples>360</samples>
            <resolution>1</resolution>
            <min_angle>-3.14159</min_angle>
            <max_angle>3.14159</max_angle>
          </horizontal>
        </scan>
        <range>
          <min>0.12</min>
          <max>8.0</max>
          <resolution>0.015</resolution>
        </range>
        <noise>
          <type>gaussian</type>
          <mean>0.0</mean>
          <stddev>0.01</stddev>
        </noise>
      </ray>
      <plugin name="gazebo_ros_lidar_controller" filename="libgazebo_ros_ray_sensor.so">
        <ros>
          <remapping>~/out:=scan</remapping>
        </ros>
        <output_type>sensor_msgs/LaserScan</output_type>
        <frame_name>lidar_link</frame_name>
      </plugin>
    </sensor>
  </gazebo>
  <gazebo reference="camera_link">
    <sensor name="camera" type="camera">
      <pose> 0 0 0 0 0 0 </pose>
      <visualize>true</visualize>
      <update_rate>30.0</update_rate>
      <camera>
        <horizontal_fov>1.089</horizontal_fov>
        <image>
          <format>R8G8B8</format>
          <width>640</width>
          <height>480</height>
        </image>
        <clip>
          <near>0.05</near>
          <far>8.0</far>
        </clip>
      </camera>
      <plugin name="camera_controller" filename="libgazebo_ros_camera.so">
        <frame_name>camera_link_optical</frame_name>
      </plugin>
    </sensor>
  </gazebo>
  </robot>
